2017-11-24 14:02:08 ERROR (MainThread) [homeassistant.helpers.entity] Update for sensor.pws_location fails
Traceback (most recent call last):
  File "/srv/homeassistant/homeassistant_venv/lib/python3.5/site-packages/urllib3/connectionpool.py", line 387, in _make_request
    six.raise_from(e, None)
  File "<string>", line 2, in raise_from
  File "/srv/homeassistant/homeassistant_venv/lib/python3.5/site-packages/urllib3/connectionpool.py", line 383, in _make_request
    httplib_response = conn.getresponse()
  File "/usr/lib/python3.5/http/client.py", line 1198, in getresponse
    response.begin()
  File "/usr/lib/python3.5/http/client.py", line 297, in begin
    version, status, reason = self._read_status()
  File "/usr/lib/python3.5/http/client.py", line 258, in _read_status
    line = str(self.fp.readline(_MAXLINE + 1), "iso-8859-1")
  File "/usr/lib/python3.5/socket.py", line 576, in readinto
    return self._sock.recv_into(b)
socket.timeout: timed out

During handling of the above exception, another exception occurred:

Traceback (most recent call last):
  File "/srv/homeassistant/homeassistant_venv/lib/python3.5/site-packages/requests/adapters.py", line 440, in send
    timeout=timeout
  File "/srv/homeassistant/homeassistant_venv/lib/python3.5/site-packages/urllib3/connectionpool.py", line 639, in urlopen
    _stacktrace=sys.exc_info()[2])
  File "/srv/homeassistant/homeassistant_venv/lib/python3.5/site-packages/urllib3/util/retry.py", line 357, in increment
    raise six.reraise(type(error), error, _stacktrace)
  File "/srv/homeassistant/homeassistant_venv/lib/python3.5/site-packages/urllib3/packages/six.py", line 686, in reraise
    raise value
  File "/srv/homeassistant/homeassistant_venv/lib/python3.5/site-packages/urllib3/connectionpool.py", line 601, in urlopen
    chunked=chunked)
  File "/srv/homeassistant/homeassistant_venv/lib/python3.5/site-packages/urllib3/connectionpool.py", line 389, in _make_request
    self._raise_timeout(err=e, url=url, timeout_value=read_timeout)
  File "/srv/homeassistant/homeassistant_venv/lib/python3.5/site-packages/urllib3/connectionpool.py", line 309, in _raise_timeout
    raise ReadTimeoutError(self, url, "Read timed out. (read timeout=%s)" % timeout_value)
urllib3.exceptions.ReadTimeoutError: HTTPConnectionPool(host='api.wunderground.com', port=80): Read timed out. (read timeout=10)

During handling of the above exception, another exception occurred:

Traceback (most recent call last):
  File "/srv/homeassistant/homeassistant_venv/lib/python3.5/site-packages/homeassistant/helpers/entity.py", line 199, in async_update_ha_state
    yield from self.async_device_update()
  File "/srv/homeassistant/homeassistant_venv/lib/python3.5/site-packages/homeassistant/helpers/entity.py", line 306, in async_device_update
    yield from self.hass.async_add_job(self.update)
  File "/usr/lib/python3.5/asyncio/futures.py", line 380, in __iter__
    yield self  # This tells Task to wait for completion.
  File "/usr/lib/python3.5/asyncio/tasks.py", line 304, in _wakeup
    future.result()
  File "/usr/lib/python3.5/asyncio/futures.py", line 293, in result
    raise self._exception
  File "/usr/lib/python3.5/concurrent/futures/thread.py", line 55, in run
    result = self.fn(*self.args, **self.kwargs)
  File "/srv/homeassistant/homeassistant_venv/lib/python3.5/site-packages/homeassistant/components/sensor/wunderground.py", line 720, in update
    self.rest.update()
  File "/srv/homeassistant/homeassistant_venv/lib/python3.5/site-packages/homeassistant/util/__init__.py", line 306, in wrapper
    result = method(*args, **kwargs)
  File "/srv/homeassistant/homeassistant_venv/lib/python3.5/site-packages/homeassistant/components/sensor/wunderground.py", line 755, in update
    result = requests.get(self._build_url(), timeout=10).json()
  File "/srv/homeassistant/homeassistant_venv/lib/python3.5/site-packages/requests/api.py", line 72, in get
    return request('get', url, params=params, **kwargs)
  File "/srv/homeassistant/homeassistant_venv/lib/python3.5/site-packages/requests/api.py", line 58, in request
    return session.request(method=method, url=url, **kwargs)
  File "/srv/homeassistant/homeassistant_venv/lib/python3.5/site-packages/requests/sessions.py", line 508, in request
    resp = self.send(prep, **send_kwargs)
  File "/srv/homeassistant/homeassistant_venv/lib/python3.5/site-packages/requests/sessions.py", line 618, in send
    r = adapter.send(request, **kwargs)
  File "/srv/homeassistant/homeassistant_venv/lib/python3.5/site-packages/requests/adapters.py", line 521, in send
    raise ReadTimeout(e, request=request)
requests.exceptions.ReadTimeout: HTTPConnectionPool(host='api.wunderground.com', port=80): Read timed out. (read timeout=10)
2017-11-24 16:20:44 ERROR (Thread-6) [homeassistant.components.sensor.darksky] Unable to connect to Dark Sky. ('Connection aborted.', OSError(0, 'Error'))
2017-11-24 16:25:29 ERROR (MainThread) [homeassistant.core] Timer got out of sync. Resetting
2017-11-24 16:28:42 ERROR (MainThread) [aiohttp.server] Error handling request
Traceback (most recent call last):
  File "/srv/homeassistant/homeassistant_venv/lib/python3.5/site-packages/urllib3/connection.py", line 141, in _new_conn
    (self.host, self.port), self.timeout, **extra_kw)
  File "/srv/homeassistant/homeassistant_venv/lib/python3.5/site-packages/urllib3/util/connection.py", line 83, in create_connection
    raise err
  File "/srv/homeassistant/homeassistant_venv/lib/python3.5/site-packages/urllib3/util/connection.py", line 73, in create_connection
    sock.connect(sa)
ConnectionRefusedError: [Errno 111] Connection refused

During handling of the above exception, another exception occurred:

Traceback (most recent call last):
  File "/srv/homeassistant/homeassistant_venv/lib/python3.5/site-packages/urllib3/connectionpool.py", line 601, in urlopen
    chunked=chunked)
  File "/srv/homeassistant/homeassistant_venv/lib/python3.5/site-packages/urllib3/connectionpool.py", line 357, in _make_request
    conn.request(method, url, **httplib_request_kw)
  File "/usr/lib/python3.5/http/client.py", line 1107, in request
    self._send_request(method, url, body, headers)
  File "/usr/lib/python3.5/http/client.py", line 1152, in _send_request
    self.endheaders(body)
  File "/usr/lib/python3.5/http/client.py", line 1103, in endheaders
    self._send_output(message_body)
  File "/usr/lib/python3.5/http/client.py", line 934, in _send_output
    self.send(msg)
  File "/usr/lib/python3.5/http/client.py", line 877, in send
    self.connect()
  File "/srv/homeassistant/homeassistant_venv/lib/python3.5/site-packages/urllib3/connection.py", line 166, in connect
    conn = self._new_conn()
  File "/srv/homeassistant/homeassistant_venv/lib/python3.5/site-packages/urllib3/connection.py", line 150, in _new_conn
    self, "Failed to establish a new connection: %s" % e)
urllib3.exceptions.NewConnectionError: <urllib3.connection.HTTPConnection object at 0x57ebb9d0>: Failed to establish a new connection: [Errno 111] Connection refused

During handling of the above exception, another exception occurred:

Traceback (most recent call last):
  File "/srv/homeassistant/homeassistant_venv/lib/python3.5/site-packages/requests/adapters.py", line 440, in send
    timeout=timeout
  File "/srv/homeassistant/homeassistant_venv/lib/python3.5/site-packages/urllib3/connectionpool.py", line 668, in urlopen
    **response_kw)
  File "/srv/homeassistant/homeassistant_venv/lib/python3.5/site-packages/urllib3/connectionpool.py", line 668, in urlopen
    **response_kw)
  File "/srv/homeassistant/homeassistant_venv/lib/python3.5/site-packages/urllib3/connectionpool.py", line 668, in urlopen
    **response_kw)
  File "/srv/homeassistant/homeassistant_venv/lib/python3.5/site-packages/urllib3/connectionpool.py", line 639, in urlopen
    _stacktrace=sys.exc_info()[2])
  File "/srv/homeassistant/homeassistant_venv/lib/python3.5/site-packages/urllib3/util/retry.py", line 388, in increment
    raise MaxRetryError(_pool, url, error or ResponseError(cause))
urllib3.exceptions.MaxRetryError: HTTPConnectionPool(host='10.40.0.12', port=80): Max retries exceeded with url: /cgi-bin/snapshot.cgi?channel=0 (Caused by NewConnectionError('<urllib3.connection.HTTPConnection object at 0x57ebb9d0>: Failed to establish a new connection: [Errno 111] Connection refused',))

During handling of the above exception, another exception occurred:

Traceback (most recent call last):
  File "/srv/homeassistant/homeassistant_venv/lib/python3.5/site-packages/aiohttp/web_protocol.py", line 416, in start
    resp = yield from self._request_handler(request)
  File "/srv/homeassistant/homeassistant_venv/lib/python3.5/site-packages/aiohttp/web.py", line 323, in _handle
    resp = yield from handler(request)
  File "/srv/homeassistant/homeassistant_venv/lib/python3.5/site-packages/homeassistant/components/http/ban.py", line 58, in ban_middleware
    return (yield from handler(request))
  File "/usr/lib/python3.5/asyncio/coroutines.py", line 213, in coro
    res = yield from res
  File "/usr/lib/python3.5/asyncio/coroutines.py", line 213, in coro
    res = yield from res
  File "/srv/homeassistant/homeassistant_venv/lib/python3.5/site-packages/homeassistant/components/http/__init__.py", line 430, in handle
    result = yield from result
  File "/srv/homeassistant/homeassistant_venv/lib/python3.5/site-packages/homeassistant/components/camera/__init__.py", line 387, in get
    response = yield from self.handle(request, camera)
  File "/srv/homeassistant/homeassistant_venv/lib/python3.5/site-packages/homeassistant/components/camera/__init__.py", line 407, in handle
    image = yield from camera.async_camera_image()
  File "/usr/lib/python3.5/asyncio/futures.py", line 380, in __iter__
    yield self  # This tells Task to wait for completion.
  File "/usr/lib/python3.5/asyncio/tasks.py", line 304, in _wakeup
    future.result()
  File "/usr/lib/python3.5/asyncio/futures.py", line 293, in result
    raise self._exception
  File "/usr/lib/python3.5/concurrent/futures/thread.py", line 55, in run
    result = self.fn(*self.args, **self.kwargs)
  File "/srv/homeassistant/homeassistant_venv/lib/python3.5/site-packages/homeassistant/components/camera/amcrest.py", line 67, in camera_image
    response = self._camera.snapshot(channel=self._resolution)
  File "/srv/homeassistant/homeassistant_venv/lib/python3.5/site-packages/amcrest/snapshot.py", line 48, in snapshot
    timeout_cmd=timeout
  File "/srv/homeassistant/homeassistant_venv/lib/python3.5/site-packages/amcrest/http.py", line 153, in command
    timeout=self._timeout_protocol,
  File "/srv/homeassistant/homeassistant_venv/lib/python3.5/site-packages/requests/sessions.py", line 521, in get
    return self.request('GET', url, **kwargs)
  File "/srv/homeassistant/homeassistant_venv/lib/python3.5/site-packages/requests/sessions.py", line 508, in request
    resp = self.send(prep, **send_kwargs)
  File "/srv/homeassistant/homeassistant_venv/lib/python3.5/site-packages/requests/sessions.py", line 618, in send
    r = adapter.send(request, **kwargs)
  File "/srv/homeassistant/homeassistant_venv/lib/python3.5/site-packages/requests/adapters.py", line 508, in send
    raise ConnectionError(e, request=request)
requests.exceptions.ConnectionError: HTTPConnectionPool(host='10.40.0.12', port=80): Max retries exceeded with url: /cgi-bin/snapshot.cgi?channel=0 (Caused by NewConnectionError('<urllib3.connection.HTTPConnection object at 0x57ebb9d0>: Failed to establish a new connection: [Errno 111] Connection refused',))
