2018-11-10 10:36:17 ERROR (MainThread) [homeassistant.components.sensor] fedex: Error on device update!
Traceback (most recent call last):
  File "/srv/homeassistant/homeassistant_venv/lib/python3.5/site-packages/fedexdeliverymanager/__init__.py", line 64, in wrapped
    return function(*args)
  File "/srv/homeassistant/homeassistant_venv/lib/python3.5/site-packages/fedexdeliverymanager/__init__.py", line 103, in get_packages
    raise FedexError(err)
fedexdeliverymanager.FedexError: failed to get shipment list: Relogin

During handling of the above exception, another exception occurred:

Traceback (most recent call last):
  File "/srv/homeassistant/homeassistant_venv/lib/python3.5/site-packages/homeassistant/helpers/entity_platform.py", line 251, in _async_add_entity
    await entity.async_device_update(warning=False)
  File "/srv/homeassistant/homeassistant_venv/lib/python3.5/site-packages/homeassistant/helpers/entity.py", line 349, in async_device_update
    await self.hass.async_add_executor_job(self.update)
  File "/usr/lib/python3.5/asyncio/futures.py", line 380, in __iter__
    yield self  # This tells Task to wait for completion.
  File "/usr/lib/python3.5/asyncio/tasks.py", line 304, in _wakeup
    future.result()
  File "/usr/lib/python3.5/asyncio/futures.py", line 293, in result
    raise self._exception
  File "/usr/lib/python3.5/concurrent/futures/thread.py", line 55, in run
    result = self.fn(*self.args, **self.kwargs)
  File "/srv/homeassistant/homeassistant_venv/lib/python3.5/site-packages/homeassistant/util/__init__.py", line 324, in wrapper
    result = method(*args, **kwargs)
  File "/srv/homeassistant/homeassistant_venv/lib/python3.5/site-packages/homeassistant/components/sensor/fedex.py", line 93, in _update
    for package in fedexdeliverymanager.get_packages(self._session):
  File "/srv/homeassistant/homeassistant_venv/lib/python3.5/site-packages/fedexdeliverymanager/__init__.py", line 66, in wrapped
    _login(*args)
  File "/srv/homeassistant/homeassistant_venv/lib/python3.5/site-packages/fedexdeliverymanager/__init__.py", line 82, in _login
    raise FedexError('could not login')
fedexdeliverymanager.FedexError: could not login
2018-11-10 10:36:27 ERROR (MainThread) [homeassistant.components.device_tracker] Error setting up platform google_maps
Traceback (most recent call last):
  File "/srv/homeassistant/homeassistant_venv/lib/python3.5/site-packages/homeassistant/components/device_tracker/__init__.py", line 184, in async_setup_platform
    disc_info)
  File "/usr/lib/python3.5/asyncio/futures.py", line 380, in __iter__
    yield self  # This tells Task to wait for completion.
  File "/usr/lib/python3.5/asyncio/tasks.py", line 304, in _wakeup
    future.result()
  File "/usr/lib/python3.5/asyncio/futures.py", line 293, in result
    raise self._exception
  File "/usr/lib/python3.5/concurrent/futures/thread.py", line 55, in run
    result = self.fn(*self.args, **self.kwargs)
  File "/srv/homeassistant/homeassistant_venv/lib/python3.5/site-packages/homeassistant/components/device_tracker/google_maps.py", line 46, in setup_scanner
    scanner = GoogleMapsScanner(hass, config, see)
  File "/srv/homeassistant/homeassistant_venv/lib/python3.5/site-packages/homeassistant/components/device_tracker/google_maps.py", line 65, in __init__
    hass.config.path(CREDENTIALS_FILE))
  File "/srv/homeassistant/homeassistant_venv/lib/python3.5/site-packages/locationsharinglib/locationsharinglib.py", line 387, in __init__
    cookies_file=cookies_file)
  File "/srv/homeassistant/homeassistant_venv/lib/python3.5/site-packages/locationsharinglib/locationsharinglib.py", line 211, in __init__
    if cookies_file and self._validate_cookie(cookies_file):
  File "/srv/homeassistant/homeassistant_venv/lib/python3.5/site-packages/locationsharinglib/locationsharinglib.py", line 238, in _validate_cookie
    raise InvalidCookies(message)
locationsharinglib.locationsharinglibexceptions.InvalidCookies: The cookies provided do not provide a valid session.Please authenticate normally and save a valid session again
2018-11-10 10:37:47 ERROR (MainThread) [homeassistant.components.sensor.template] Could not render icon template Thermostat Battery: UndefinedError: 'mappingproxy object' has no attribute 'battery_level'
2018-11-10 10:37:47 ERROR (MainThread) [homeassistant.components.sensor.template] Could not render icon template Thermostat Battery: UndefinedError: 'mappingproxy object' has no attribute 'battery_level'
2018-11-10 10:37:49 ERROR (Thread-10) [homeassistant.core] Error doing job: Future exception was never retrieved
Traceback (most recent call last):
  File "/usr/lib/python3.5/concurrent/futures/thread.py", line 55, in run
    result = self.fn(*self.args, **self.kwargs)
  File "/srv/homeassistant/homeassistant_venv/lib/python3.5/site-packages/homeassistant/components/sensor/waze_travel_time.py", line 74, in <lambda>
    EVENT_HOMEASSISTANT_START, lambda _: sensor.update())
  File "/srv/homeassistant/homeassistant_venv/lib/python3.5/site-packages/homeassistant/components/sensor/waze_travel_time.py", line 204, in update
    routes = params.calc_all_routes_info(real_time=self._realtime)
  File "/srv/homeassistant/homeassistant_venv/lib/python3.5/site-packages/WazeRouteCalculator/WazeRouteCalculator.py", line 145, in calc_all_routes_info
    routes = self.get_route(npaths, time_delta)
  File "/srv/homeassistant/homeassistant_venv/lib/python3.5/site-packages/WazeRouteCalculator/WazeRouteCalculator.py", line 95, in get_route
    response_json = response.json()
  File "/srv/homeassistant/homeassistant_venv/lib/python3.5/site-packages/requests/models.py", line 897, in json
    return complexjson.loads(self.text, **kwargs)
  File "/usr/lib/python3.5/json/__init__.py", line 319, in loads
    return _default_decoder.decode(s)
  File "/usr/lib/python3.5/json/decoder.py", line 339, in decode
    obj, end = self.raw_decode(s, idx=_w(s, 0).end())
  File "/usr/lib/python3.5/json/decoder.py", line 357, in raw_decode
    raise JSONDecodeError("Expecting value", s, err.value) from None
json.decoder.JSONDecodeError: Expecting value: line 1 column 1 (char 0)
2018-11-10 10:37:49 ERROR (Thread-10) [homeassistant.core] Error doing job: Future exception was never retrieved
Traceback (most recent call last):
  File "/usr/lib/python3.5/concurrent/futures/thread.py", line 55, in run
    result = self.fn(*self.args, **self.kwargs)
  File "/srv/homeassistant/homeassistant_venv/lib/python3.5/site-packages/homeassistant/components/sensor/waze_travel_time.py", line 74, in <lambda>
    EVENT_HOMEASSISTANT_START, lambda _: sensor.update())
  File "/srv/homeassistant/homeassistant_venv/lib/python3.5/site-packages/homeassistant/components/sensor/waze_travel_time.py", line 204, in update
    routes = params.calc_all_routes_info(real_time=self._realtime)
  File "/srv/homeassistant/homeassistant_venv/lib/python3.5/site-packages/WazeRouteCalculator/WazeRouteCalculator.py", line 145, in calc_all_routes_info
    routes = self.get_route(npaths, time_delta)
  File "/srv/homeassistant/homeassistant_venv/lib/python3.5/site-packages/WazeRouteCalculator/WazeRouteCalculator.py", line 95, in get_route
    response_json = response.json()
  File "/srv/homeassistant/homeassistant_venv/lib/python3.5/site-packages/requests/models.py", line 897, in json
    return complexjson.loads(self.text, **kwargs)
  File "/usr/lib/python3.5/json/__init__.py", line 319, in loads
    return _default_decoder.decode(s)
  File "/usr/lib/python3.5/json/decoder.py", line 339, in decode
    obj, end = self.raw_decode(s, idx=_w(s, 0).end())
  File "/usr/lib/python3.5/json/decoder.py", line 357, in raw_decode
    raise JSONDecodeError("Expecting value", s, err.value) from None
json.decoder.JSONDecodeError: Expecting value: line 1 column 1 (char 0)
2018-11-10 12:55:55 ERROR (MainThread) [homeassistant.components.sensor.wunderground] Error fetching WUnderground data: TimeoutError()
2018-11-10 15:35:59 ERROR (MainThread) [homeassistant.components.sensor.wunderground] Error fetching WUnderground data: TimeoutError()
2018-11-10 20:18:07 ERROR (MainThread) [homeassistant.helpers.entity] Update for sensor.brayden9751z fails
Traceback (most recent call last):
  File "/srv/homeassistant/homeassistant_venv/lib/python3.5/site-packages/homeassistant/helpers/entity.py", line 221, in async_update_ha_state
    await self.async_device_update()
  File "/srv/homeassistant/homeassistant_venv/lib/python3.5/site-packages/homeassistant/helpers/entity.py", line 349, in async_device_update
    await self.hass.async_add_executor_job(self.update)
  File "/usr/lib/python3.5/asyncio/futures.py", line 380, in __iter__
    yield self  # This tells Task to wait for completion.
  File "/usr/lib/python3.5/asyncio/tasks.py", line 304, in _wakeup
    future.result()
  File "/usr/lib/python3.5/asyncio/futures.py", line 293, in result
    raise self._exception
  File "/usr/lib/python3.5/concurrent/futures/thread.py", line 55, in run
    result = self.fn(*self.args, **self.kwargs)
  File "/srv/homeassistant/homeassistant_venv/lib/python3.5/site-packages/homeassistant/components/sensor/xbox_live.py", line 119, in update
    presence = self._api.get_user_presence(self._xuid)
  File "/srv/homeassistant/homeassistant_venv/lib/python3.5/site-packages/xboxapi/xbox_api.py", line 56, in get_user_presence
    return res.json()
  File "/srv/homeassistant/homeassistant_venv/lib/python3.5/site-packages/requests/models.py", line 897, in json
    return complexjson.loads(self.text, **kwargs)
  File "/usr/lib/python3.5/json/__init__.py", line 319, in loads
    return _default_decoder.decode(s)
  File "/usr/lib/python3.5/json/decoder.py", line 339, in decode
    obj, end = self.raw_decode(s, idx=_w(s, 0).end())
  File "/usr/lib/python3.5/json/decoder.py", line 357, in raw_decode
    raise JSONDecodeError("Expecting value", s, err.value) from None
json.decoder.JSONDecodeError: Expecting value: line 1 column 1 (char 0)
2018-11-10 20:18:08 ERROR (MainThread) [homeassistant.helpers.entity] Update for sensor.supersarah83 fails
Traceback (most recent call last):
  File "/srv/homeassistant/homeassistant_venv/lib/python3.5/site-packages/homeassistant/helpers/entity.py", line 221, in async_update_ha_state
    await self.async_device_update()
  File "/srv/homeassistant/homeassistant_venv/lib/python3.5/site-packages/homeassistant/helpers/entity.py", line 349, in async_device_update
    await self.hass.async_add_executor_job(self.update)
  File "/usr/lib/python3.5/asyncio/futures.py", line 380, in __iter__
    yield self  # This tells Task to wait for completion.
  File "/usr/lib/python3.5/asyncio/tasks.py", line 304, in _wakeup
    future.result()
  File "/usr/lib/python3.5/asyncio/futures.py", line 293, in result
    raise self._exception
  File "/usr/lib/python3.5/concurrent/futures/thread.py", line 55, in run
    result = self.fn(*self.args, **self.kwargs)
  File "/srv/homeassistant/homeassistant_venv/lib/python3.5/site-packages/homeassistant/components/sensor/xbox_live.py", line 119, in update
    presence = self._api.get_user_presence(self._xuid)
  File "/srv/homeassistant/homeassistant_venv/lib/python3.5/site-packages/xboxapi/xbox_api.py", line 56, in get_user_presence
    return res.json()
  File "/srv/homeassistant/homeassistant_venv/lib/python3.5/site-packages/requests/models.py", line 897, in json
    return complexjson.loads(self.text, **kwargs)
  File "/usr/lib/python3.5/json/__init__.py", line 319, in loads
    return _default_decoder.decode(s)
  File "/usr/lib/python3.5/json/decoder.py", line 339, in decode
    obj, end = self.raw_decode(s, idx=_w(s, 0).end())
  File "/usr/lib/python3.5/json/decoder.py", line 357, in raw_decode
    raise JSONDecodeError("Expecting value", s, err.value) from None
json.decoder.JSONDecodeError: Expecting value: line 1 column 1 (char 0)
2018-11-10 23:15:37 ERROR (MainThread) [homeassistant.components.sensor.wunderground] Error fetching WUnderground data: TimeoutError()
2018-11-11 01:15:00 ERROR (MainThread) [homeassistant.core] Error doing job: Task exception was never retrieved
Traceback (most recent call last):
  File "/usr/lib/python3.5/asyncio/tasks.py", line 241, in _step
    result = coro.throw(exc)
  File "/srv/homeassistant/homeassistant_venv/lib/python3.5/site-packages/homeassistant/helpers/service.py", line 224, in _handle_service_platform_call
    await getattr(entity, func)(**data)
  File "/usr/lib/python3.5/asyncio/futures.py", line 380, in __iter__
    yield self  # This tells Task to wait for completion.
  File "/usr/lib/python3.5/asyncio/tasks.py", line 304, in _wakeup
    future.result()
  File "/usr/lib/python3.5/asyncio/futures.py", line 293, in result
    raise self._exception
  File "/usr/lib/python3.5/concurrent/futures/thread.py", line 55, in run
    result = self.fn(*self.args, **self.kwargs)
  File "/srv/homeassistant/homeassistant_venv/lib/python3.5/site-packages/homeassistant/components/media_player/__init__.py", line 493, in turn_off
    raise NotImplementedError()
NotImplementedError
2018-11-11 04:30:45 ERROR (MainThread) [homeassistant.components.sensor.wunderground] Error fetching WUnderground data: TimeoutError()
